use std::num::ParseIntError;

// With the return type rewritten, we use pattern matching without `unwrap()`.
fn multiply(first_number_str: &str, second_number_str: &str) -> Result<i32, ParseIntError> {
    match first_number_str.parse::<i32>() {
        Ok(first_number) => match second_number_str.parse::<i32>() {
            Ok(second_number) => Ok(first_number * second_number),
            Err(e) => Err(e),
        },
        Err(e) => Err(e),
    }
}

// 使用 map, and_then 来实现 match 相同的逻辑
fn multiply_2(first_number_str: &str, second_number_str: &str) -> Result<i32, ParseIntError> {
    first_number_str.parse::<i32>().and_then(|first_number| {
        second_number_str
            .parse::<i32>()
            .map(|second_number| first_number * second_number)
    })
}

fn print(result: Result<i32, ParseIntError>) {
    match result {
        Ok(n) => println!("n is {}", n),
        Err(e) => println!("Error: {}", e),
    }
}

fn main() {
    // This still presents a reasonable answer.
    let twenty = multiply("10", "2");
    print(twenty);

    // The following now provides a much more helpful error message.
    let tt = multiply("t", "2");
    print(tt);

    // This still presents a reasonable answer.
    let twenty = multiply_2("10", "2");
    print(twenty);

    // The following now provides a much more helpful error message.
    let tt = multiply_2("t", "2");
    print(tt);
}
